<?xml version="1.0" encoding="utf-8"?>
<robot name="dummy_robot">

  <link name="base_link">
    <inertial>
      <origin xyz="-0.000049 -0.000002 -0.008721" rpy="0 0 0"/>
      <mass value="1.009050"/>
      <inertia ixx="0.005149" ixy="0.0" ixz="-0.000072" iyy="0.001621" iyz="0.0" izz="0.004071"/>
    </inertial>
    <visual>
      <origin xyz="0 0 0" rpy="0 0 0"/>
      <geometry>
        <mesh filename="package://dummy_robot/meshes/base_link.STL"/>
      </geometry>
      <material name="">
        <color rgba="0.79216 0.81961 0.93333 1"/>
      </material>
    </visual>
    <collision>
      <origin xyz="0 0 0" rpy="0 0 0"/>
      <geometry>
        <mesh filename="package://dummy_robot/meshes/base_link.STL"/>
      </geometry>
    </collision>
  </link>

  <link name="left_roll_link">
    <inertial>
      <origin xyz="-0.032001 -0.000022 0.097858" rpy="0 0 0"/>
      <mass value="0.404054"/>
      <inertia ixx="0.000285" ixy="0.0" ixz="-0.000031" iyy="0.000449" iyz="0.0" izz="0.000403"/>
    </inertial>
    <visual>
      <origin xyz="0 0 0" rpy="0 0 0"/>
      <geometry>
        <mesh filename="package://dummy_robot/meshes/left_roll_link.STL"/>
      </geometry>
      <material name="">
        <color rgba="1 1 1 1"/>
      </material>
    </visual>
    <collision>
      <origin xyz="0 0 0" rpy="0 0 0"/>
      <geometry>
        <mesh filename="package://dummy_robot/meshes/left_roll_link.STL"/>
      </geometry>
    </collision>
  </link>

  <joint name="left_roll_joint" type="revolute">
    <origin xyz="0.028789 0.065014 -0.024742" rpy="1.5708 0 -1.5708"/>
    <parent link="base_link"/>
    <child link="left_roll_link"/>
    <axis xyz="0 0 1"/>
    <limit lower="-0.873" upper="0.209" effort="7.7" velocity="23"/>
  </joint>

  <link name="left_upper_leg_link">
    <inertial>
      <origin xyz="-0.009355 -0.010527 0.084193" rpy="0 0 0"/>
      <mass value="0.480436"/>
      <inertia ixx="0.000565" ixy="0.000250" ixz="0.000083" iyy="0.000562" iyz="0.000094" izz="0.000772"/>
    </inertial>
    <visual>
      <origin xyz="0 0 0" rpy="0 0 0"/>
      <geometry>
        <mesh filename="package://dummy_robot/meshes/left_upper_leg_link.STL"/>
      </geometry>
      <material name="">
        <color rgba="1 1 1 1"/>
      </material>
    </visual>
    <collision>
      <origin xyz="0 0 0" rpy="0 0 0"/>
      <geometry>
        <mesh filename="package://dummy_robot/meshes/left_upper_leg_link.STL"/>
      </geometry>
    </collision>
  </link>

  <joint name="left_upper_leg_joint" type="revolute">
    <origin xyz="-0.066486 0 0.101" rpy="0 1.5708 0"/>
    <parent link="left_roll_link"/>
    <child link="left_upper_leg_link"/>
    <axis xyz="0 0 1"/>
    <limit lower="-0.785398" upper="0.785398" effort="7.7" velocity="23"/>
  </joint>

  <link name="left_lower_leg_link">
    <inertial>
      <origin xyz="0.043145 0.025235 -0.015000" rpy="0 0 0"/>
      <mass value="0.085199"/>
      <inertia ixx="0.000101" ixy="0.000149" ixz="0.0" iyy="0.000265" iyz="0.0" izz="0.000360"/>
    </inertial>
    <visual>
      <origin xyz="0 0 0" rpy="0 0 0"/>
      <geometry>
        <mesh filename="package://dummy_robot/meshes/left_lower_leg_link.STL"/>
      </geometry>
      <material name="">
        <color rgba="0.792156862745098 0.819607843137255 0.933333333333333 1"/>
      </material>
    </visual>
    <collision>
      <origin xyz="0 0 0" rpy="0 0 0"/>
      <geometry>
        <mesh filename="package://dummy_robot/meshes/left_lower_leg_link.STL"/>
      </geometry>
    </collision>
  </link>

  <joint name="left_lower_leg_joint" type="revolute">
    <origin xyz="-0.091922 -0.091926 0.057" rpy="-3.1416 0 0"/>
    <parent link="left_upper_leg_link"/>
    <child link="left_lower_leg_link"/>
    <axis xyz="0 0 1"/>
    <limit lower="-0.523599" upper="0.785398" effort="7.7" velocity="23"/>
  </joint>

  <link name="right_roll_link">
    <inertial>
      <origin xyz="0.032001 -0.000058 0.097814" rpy="0 0 0"/>
      <mass value="0.404054"/>
      <inertia ixx="0.000285" ixy="-0.000001" ixz="0.000030" iyy="0.000449" iyz="0.0" izz="0.000403"/>
    </inertial>
    <visual>
      <origin xyz="0 0 0" rpy="0 0 0"/>
      <geometry>
        <mesh filename="package://dummy_robot/meshes/right_roll_link.STL"/>
      </geometry>
      <material name="">
        <color rgba="1 1 1 1"/>
      </material>
    </visual>
    <collision>
      <origin xyz="0 0 0" rpy="0 0 0"/>
      <geometry>
        <mesh filename="package://dummy_robot/meshes/right_roll_link.STL"/>
      </geometry>
    </collision>
  </link>

  <joint name="right_roll_joint" type="revolute">
    <origin xyz="0.028789 -0.065014 -0.024742" rpy="1.5708 0 -1.5708"/>
    <parent link="base_link"/>
    <child link="right_roll_link"/>
    <axis xyz="0 0 1"/>
    <limit lower="-0.209" upper="0.873" effort="7.7" velocity="23"/>
  </joint>

  <link name="right_upper_leg_link">
    <inertial>
      <origin xyz="-0.009340 0.010565 0.084193" rpy="0 0 0"/>
      <mass value="0.480436"/>
      <inertia ixx="0.000565" ixy="-0.000250" ixz="0.000083" iyy="0.000562" iyz="-0.000094" izz="0.000771"/>
    </inertial>
    <visual>
      <origin xyz="0 0 0" rpy="0 0 0"/>
      <geometry>
        <mesh filename="package://dummy_robot/meshes/right_upper_leg_link.STL"/>
      </geometry>
      <material name="">
        <color rgba="1 1 1 1"/>
      </material>
    </visual>
    <collision>
      <origin xyz="0 0 0" rpy="0 0 0"/>
      <geometry>
        <mesh filename="package://dummy_robot/meshes/right_upper_leg_link.STL"/>
      </geometry>
    </collision>
  </link>

  <joint name="right_upper_leg_joint" type="revolute">
    <origin xyz="0.066486 0 0.101" rpy="3.1416 1.5708 0"/>
    <parent link="right_roll_link"/>
    <child link="right_upper_leg_link"/>
    <axis xyz="0 0 1"/>
    <limit lower="-0.785398" upper="0.785398" effort="7.7" velocity="23"/>
  </joint>

  <link name="right_lower_leg_link">
    <inertial>
      <origin xyz="0.043145 -0.025235 -0.015000" rpy="0 0 0"/>
      <mass value="0.085199"/>
      <inertia ixx="0.000101" ixy="-0.000149" ixz="0.0" iyy="0.000265" iyz="0.0" izz="0.000360"/>
    </inertial>
    <visual>
      <origin xyz="0 0 0" rpy="0 0 0"/>
      <geometry>
        <mesh filename="package://dummy_robot/meshes/right_lower_leg_link.STL"/>
      </geometry>
      <material name="">
        <color rgba="0.792156862745098 0.819607843137255 0.933333333333333 1"/>
      </material>
    </visual>
    <collision>
      <origin xyz="0 0 0" rpy="0 0 0"/>
      <geometry>
        <mesh filename="package://dummy_robot/meshes/right_lower_leg_link.STL"/>
      </geometry>
    </collision>
  </link>

  <joint name="right_lower_leg_joint" type="revolute">
    <origin xyz="-0.091922 0.091926 0.057" rpy="-3.1416 0 0"/>
    <parent link="right_upper_leg_link"/>
    <child link="right_lower_leg_link"/>
    <axis xyz="0 0 1"/>
    <limit lower="-0.785398" upper="0.523599" effort="7.7" velocity="23"/>
  </joint>

</robot>
